Workbook
Name DATA1: #REF!
Name DATA10: #REF!
Name DATA11: #REF!
Name DATA12: #REF!
Name DATA13: #REF!
Name DATA14: #REF!
Name DATA15: #REF!
Name DATA16: #REF!
Name DATA17: #REF!
Name DATA18: #REF!
Name DATA19: #REF!
Name DATA2: #REF!
Name DATA20: #REF!
Name DATA3: #REF!
Name DATA4: #REF!
Name DATA5: #REF!
Name DATA6: #REF!
Name DATA7: #REF!
Name DATA8: #REF!
Name DATA9: #REF!
Name FORECAST: #REF!
Name TEST1: #REF!
Name TEST2: #REF!
Name TEST3: #REF!
Name TEST4: #REF!
Name TESTHKEY: #REF!
Name TESTKEYS: #REF!
Name TESTVKEY: #REF!
Name WORKCENTER: #REF!

Sheet DATABASE
C1: SUMMARY MACHINE OF PRESS DEPARTMENT 2026 | S1: Update | U1: 16-JUN-2026
C5: M/C Type | D5: M/C No. | E5: Machine group | F5: Status | G5: Location | H5: Maker | I5: Model | J5: Volume CC | K5: Pressure | L5: PLATE | M5: VACUUM | N5: Temp Reg | O5: EJECTOR | P5: Mold min | Q5: Day light (mm.) | R5: STOKE (mm.) | S5: RANK | U5: Remark | V5: Area Sensor Distance (mm.)
C6: INJ | D6: 13 | E6: INJECT 1.6 L 500x600 HOT EM | F6: พร้อมใช้งาน | G6: PRESS 1 | H6: SANYU | I6: VA | J6: 1600 | K6: 150T | L6: 500x600 | N6: 2 Zone | O6: 3RT | P6: 245 | Q6: 645 | R6: =Q6-P6 -> 400
D7: 14 | E7: INJECT 1.6 L 500x600 HOT EM | F7: พร้อมใช้งาน | G7: PRESS 1 | H7: SANYU | I7: VA | J7: 1600 | K7: 150T | L7: 500x600 | M7: O | N7: 2 Zone | O7: 3RT | P7: 245 | Q7: 645 | R7: =Q7-P7 -> 400
D8: 15 | E8: INJECT 1.6 L 500x600 HOT EM | F8: พร้อมใช้งาน | G8: PRESS 1 | H8: SANYU | I8: VA | J8: 1600 | K8: 150T | L8: 500x600 | M8: O | N8: 2 Zone | O8: 3RT | P8: 245 | Q8: 645 | R8: =Q8-P8 -> 400
D9: 16 | E9: INJECT 1.6 L 500x600 HOT EM | F9: พร้อมใช้งาน | G9: PRESS 1 | H9: SANYU | I9: VA | J9: 1600 | K9: 150T | L9: 500x600 | M9: O | N9: 2 Zone | O9: 3RT | P9: 245 | Q9: 645 | R9: =Q9-P9 -> 400
D10: 17 | E10: INJECT 1.6 L 500x600 HOT EM | F10: พร้อมใช้งาน | G10: PRESS 1 | H10: SANYU | I10: VA | J10: 1600 | K10: 150T | L10: 500x600 | N10: 2 Zone | O10: 3RT | P10: 245 | Q10: 645 | R10: =Q10-P10 -> 400
D11: 36 | E11: INJECT 1.6 L 500x600 HOT EM | F11: พร้อมใช้งาน | G11: PRESS 1 | H11: SANYU | I11: VA | J11: 1600 | K11: 150T | L11: 500x600 | M11: O | N11: 2 Zone | O11: 3RT | P11: 245 | Q11: 645 | R11: =Q11-P11 -> 400
D12: 37 | E12: INJECT 1.6 L 500x600 HOT EM | F12: พร้อมใช้งาน | G12: PRESS 1 | H12: SANYU | I12: VA | J12: 1600 | K12: 150T | L12: 500x600 | M12: O | N12: 2 Zone | O12: 3RT | P12: 245 | Q12: 645 | R12: =Q12-P12 -> 400
D13: 38 | E13: INJ 2.5 L 500x600 200T EM | F13: พร้อมใช้งาน | G13: PRESS 1 | H13: SANYU | I13: VA | J13: 2500 | K13: 150T | L13: 500x600 | M13: O | N13: 2 Zone | O13: 3RT | P13: 245 | Q13: 645 | R13: =Q13-P13 -> 400
D14: 39 | E14: INJ 2.5 L 500x600 200T EM | F14: พร้อมใช้งาน | G14: PRESS 1 | H14: SANYU | I14: VA | J14: 2500 | K14: 150T | L14: 500x600 | M14: O | N14: 2 Zone | O14: 3RT | P14: 245 | Q14: 645 | R14: =Q14-P14 -> 400
D15: 40 | E15: INJECT 1.6 L 500x600 COOL RUNNER VA | F15: พร้อมใช้งาน | G15: PRESS 1 | H15: SANYU | I15: VA | J15: 1600 | K15: 150T | L15: 500x600 | N15: 2 Zone | O15: 3RT | P15: 245 | Q15: 645 | R15: =Q15-P15 -> 400 | T15: 1 | U15: Cool runner
D16: 49 | E16: INJECT 1.6 L 500x600 COOL RUNNER VA | F16: พร้อมใช้งาน | G16: PRESS 1 | H16: SANYU | I16: VA | J16: 1600 | K16: 150T | L16: 500x600 | M16: O | N16: 3 Zone | O16: 3RT | P16: 245 | Q16: 645 | R16: =Q16-P16 -> 400 | T16: 1 | U16: Cool runner
D17: 50 | E17: INJECT 1.6 L 500x600 COOL RUNNER VA | F17: พร้อมใช้งาน | G17: PRESS 1 | H17: SANYU | I17: VA | J17: 1600 | K17: 150T | L17: 500x600 | M17: O | N17: 3 Zone | O17: 3RT | P17: 245 | Q17: 645 | R17: =Q17-P17 -> 400 | T17: 1 | U17: Cool runner
D18: 51 | E18: INJECT 1.6 L 500x600 COOL RUNNER VA | F18: พร้อมใช้งาน | G18: PRESS 1 | H18: SANYU | I18: VA | J18: 1600 | K18: 150T | L18: 500x600 | M18: O | N18: 3 Zone | O18: 3RT | P18: 245 | Q18: 645 | R18: =Q18-P18 -> 400 | T18: 1 | U18: Cool runner
D19: 53 | E19: INJECT 1.6 L 500x600 COOL RUNNER TMA | F19: พร้อมใช้งาน | G19: PRESS 1 | H19: SANYU | I19: VA | J19: 1600 | K19: 150T | L19: 500x600 | M19: O | N19: 3 Zone | O19: 3RT | P19: 245 | Q19: 645 | R19: =Q19-P19 -> 400 | T19: 1 | U19: Cool runner
D20: 54 | E20: INJECT 1.6 L 500x600 COOL RUNNER TMA | F20: พร้อมใช้งาน | G20: PRESS 1 | H20: SANYU | I20: VA | J20: 1600 | K20: 150T | L20: 500x600 | M20: O | N20: 3 Zone | O20: 3RT | P20: 245 | Q20: 645 | R20: =Q20-P20 -> 400 | T20: 1 | U20: Cool runner
D21: 55 | E21: INJECT 1.6 L 500x600 COOL RUNNER TMA | F21: พร้อมใช้งาน | G21: PRESS 1 | H21: SANYU | I21: VA | J21: 1600 | K21: 150T | L21: 500x600 | M21: O | N21: 3 Zone | O21: 3RT | P21: 245 | Q21: 645 | R21: =Q21-P21 -> 400 | T21: 1 | U21: Cool runner
D22: 56 | E22: INJECT 1.6 L 500x600 COOL RUNNER TMA | F22: พร้อมใช้งาน | G22: PRESS 1 | H22: SANYU | I22: VA | J22: 1600 | K22: 150T | L22: 500x600 | M22: O | N22: 3 Zone | O22: 3RT | P22: 245 | Q22: 645 | R22: =Q22-P22 -> 400 | T22: 1 | U22: Cool runner
D23: 57 | E23: INJECT 1.6 L 500x600 COOL RUNNER TMA | F23: พร้อมใช้งาน | G23: PRESS 1 | H23: SANYU | I23: VA | J23: 1600 | K23: 150T | L23: 500x600 | M23: O | N23: 3 Zone | O23: 3RT | P23: 245 | Q23: 645 | R23: =Q23-P23 -> 400 | T23: 1 | U23: Cool runner
D24: 58 | E24: INJECT 1.6 L 500x600 COOL RUNNER VA | F24: พร้อมใช้งาน | G24: PRESS 1 | H24: SANYU | I24: VA | J24: 1600 | K24: 150T | L24: 500x600 | N24: 2 Zone | O24: 3RT | P24: 245 | Q24: 645 | R24: =Q24-P24 -> 400 | T24: 1 | U24: Cool runner
D25: 59 | E25: INJECT 1.6 L 500x600 COOL RUNNER VA | F25: พร้อมใช้งาน | G25: PRESS 1 | H25: SANYU | I25: VA | J25: 1600 | K25: 150T | L25: 500x600 | N25: 2 Zone | O25: 3RT | P25: 245 | Q25: 645 | R25: =Q25-P25 -> 400 | T25: 1 | U25: Cool runner
D26: 60 | E26: INJECT 1.6 L 500x600 COOL RUNNER VA | F26: พร้อมใช้งาน | G26: PRESS 1 | H26: SANYU | I26: VA | J26: 1600 | K26: 150T | L26: 500x600 | N26: 2 Zone | O26: 3RT | P26: 245 | Q26: 645 | R26: =Q26-P26 -> 400 | T26: 1 | U26: Cool runner
D27: 61 | E27: INJECT 1.6 L 500x600 COOL RUNNER VA | F27: พร้อมใช้งาน | G27: PRESS 1 | H27: SANYU | I27: VA | J27: 1600 | K27: 150T | L27: 500x600 | N27: 2 Zone | O27: 3RT | P27: 245 | Q27: 645 | R27: =Q27-P27 -> 400 | T27: 1 | U27: Cool runner
D28: 63 | E28: INJECT 1.6 L 500x600 COOL RUNNER VA | F28: พร้อมใช้งาน | G28: PRESS 1 | H28: SANYU | I28: VA | J28: 1600 | K28: 150T | L28: 500x600 | N28: 2 Zone | O28: 3RT | P28: 245 | Q28: 645 | R28: =Q28-P28 -> 400 | T28: 1 | U28: Cool runner
D29: 69 | E29: INJECT 1.6 L 600x600 COOL RUNNER (Daylight 800-870 mm.) | F29: พร้อมใช้งาน | G29: PRESS 1 | H29: SANYU | I29: VC | J29: 2000 | K29: 200T | L29: 600x600 | M29: O | N29: 3 Zone | O29: 3RT | P29: 370 | Q29: 890 | R29: =Q29-P29 -> 520 | T29: 1 | U29: Cool runner
D30: 73 | E30: INJECT 1.6 L 600x600 COOL RUNNER (Daylight 800-870 mm.) | F30: พร้อมใช้งาน | G30: PRESS 1 | H30: SANYU | I30: VC | J30: 1600 | K30: 200T | L30: 600x600 | M30: O | N30: 3 Zone | O30: 3RT | P30: 315 | Q30: 810 | R30: =Q30-P30 -> 495 | T30: 1 | U30: Cool runner
D31: 74 | E31: INJECT 1.6 L 600x600 COOL RUNNER (Daylight 800-870 mm.) | F31: พร้อมใช้งาน | G31: PRESS 1 | H31: SANYU | I31: VC | J31: 1600 | K31: 200T | L31: 600x600 | M31: O | N31: 3 Zone | O31: 3RT | P31: 315 | Q31: 810 | R31: =Q31-P31 -> 495 | T31: 1 | U31: Cool runner
D32: 75 | E32: INJECT 1.6 L 600x600 COOL RUNNER VC | F32: พร้อมใช้งาน | G32: PRESS 1 | H32: SANYU | I32: VC | J32: 1600 | K32: 200T | L32: 600x600 | M32: O | N32: 3 Zone | O32: 3RT | P32: 315 | Q32: 750 | R32: =Q32-P32 -> 435 | T32: 1 | U32: Cool runner | V32: 200 มม.
D33: 76 | E33: INJECT 1.6 L 600x600 COOL RUNNER VC | F33: พร้อมใช้งาน | G33: PRESS 1 | H33: SANYU | I33: VC | J33: 1600 | K33: 200T | L33: 600x600 | M33: O | N33: 3 Zone | O33: 3RT | P33: 315 | Q33: 750 | R33: =Q33-P33 -> 435 | T33: 1 | U33: Cool runner | V33: 200 มม.
D34: 77 | E34: INJECT 1.6 L 600x600 COOL RUNNER VC | F34: พร้อมใช้งาน | G34: PRESS 1 | H34: SANYU | I34: VC | J34: 1600 | K34: 200T | L34: 600x600 | M34: O | N34: 3 Zone | O34: 3RT | P34: 315 | Q34: 690 | R34: =Q34-P34 -> 375 | T34: 1 | U34: Cool runner | V34: 150 มม.
D35: 78 | E35: INJECT 1.6 L 600x600 COOL RUNNER (Daylight 800-870 mm.) | F35: พร้อมใช้งาน | G35: PRESS 1 | H35: SANYU | I35: VC | J35: 1600 | K35: 200T | L35: 600x600 | M35: O | N35: 3 Zone | O35: 3RT | P35: 315 | Q35: 890 | R35: =Q35-P35 -> 575 | T35: 1 | U35: Cool runner
D36: 79 | E36: INJECT 1.6 L 600x600 COOL RUNNER (Daylight 800-870 mm.) | F36: พร้อมใช้งาน | G36: PRESS 1 | H36: SANYU | I36: VC | J36: 1600 | K36: 200T | L36: 600x600 | M36: O | N36: 3 Zone | O36: 3RT | P36: 315 | Q36: 890 | R36: =Q36-P36 -> 575 | T36: 1 | U36: Cool runner
D37: 80 | E37: INJECT 1.6 L 600x600 COOL RUNNER VC | F37: พร้อมใช้งาน | G37: PRESS 1 | H37: SANYU | I37: VC | J37: 1600 | K37: 200T | L37: 600x600 | M37: O | N37: 3 Zone | O37: 3RT | P37: 315 | Q37: 750 | R37: =Q37-P37 -> 435 | T37: 1 | U37: Cool runner | V37: 200 มม.
D38: 81 | E38: INJECT 1.6 L 600x600 COOL RUNNER VC | F38: พร้อมใช้งาน | G38: PRESS 1 | H38: SANYU | I38: VC | J38: 1600 | K38: 200T | L38: 600x600 | M38: O | N38: 3 Zone | O38: 3RT | P38: 315 | Q38: 690 | R38: =Q38-P38 -> 375 | T38: 1 | U38: Cool runner | V38: 200 มม.
D39: 82 | E39: INJECT 1.6 L 600x600 COOL RUNNER VC | F39: พร้อมใช้งาน | G39: PRESS 1 | H39: SANYU | I39: VC | J39: 1600 | K39: 200T | L39: 600x600 | M39: O | N39: 3 Zone | O39: 3RT | P39: 315 | Q39: 690 | R39: =Q39-P39 -> 375 | T39: 1 | U39: Cool runner | V39: 200 มม.
D40: 83 | E40: INJECT 1.6 L 600x600 COOL RUNNER VC | F40: พร้อมใช้งาน | G40: PRESS 1 | H40: SANYU | I40: VC | J40: 1600 | K40: 200T | L40: 600x600 | M40: O | N40: 3 Zone | O40: 3RT | P40: 315 | Q40: 690 | R40: =Q40-P40 -> 375 | T40: 1 | U40: Cool runner | V40: 150 มม.
D41: 84 | E41: INJECT 1.6 L 600x600 COOL RUNNER VC | F41: พร้อมใช้งาน | G41: PRESS 1 | H41: SANYU | I41: VC | J41: 1600 | K41: 200T | L41: 600x600 | M41: O | N41: 3 Zone | O41: 3RT | P41: 315 | Q41: 690 | R41: =Q41-P41 -> 375 | T41: 1 | U41: Cool runner | V41: 150 มม.
D42: 85 | E42: INJECT 1.6 L 600x600 COOL RUNNER VC | F42: พร้อมใช้งาน | G42: PRESS 1 | H42: SANYU | I42: VC | J42: 1600 | K42: 200T | L42: 600x600 | M42: O | N42: 3 Zone | O42: 3RT | P42: 315 | Q42: 750 | R42: =Q42-P42 -> 435 | T42: 1 | U42: Cool runner | V42: 200 มม.
D43: 86 | E43: INJECT 1.6 L 600x600 COOL RUNNER VC | F43: พร้อมใช้งาน | G43: PRESS 1 | H43: SANYU | I43: VC | J43: 1600 | K43: 200T | L43: 600x600 | M43: O | N43: 3 Zone | O43: 3RT | P43: 315 | Q43: 690 | R43: =Q43-P43 -> 375 | T43: 1 | U43: Cool runner
...

Sheet Sheet1
A1: Machine Type | B1: จำนวนเครื่องทั้งหมด
A2: INJECT 1.6 L 500x600 HOT EM | B2: =COUNTIF(DATABASE!$E$5:$E$72,A2) -> 7
A3: INJ 2.5 L 500x600 200T EM | B3: =COUNTIF(DATABASE!$E$5:$E$72,A3) -> 2
A4: INJECT 1.6 L 500x600 COOL RUNNER VA | B4: =COUNTIF(DATABASE!$E$5:$E$72,A4) -> 9
A5: INJECT 1.6 L 500x600 COOL RUNNER TMA | B5: =COUNTIF(DATABASE!$E$5:$E$72,A5) -> 5
A6: INJECT 1.6 L 600x600 COOL RUNNER VC | B6: =COUNTIF(DATABASE!$E$5:$E$72,A6) -> 10
A7: INJECT 1.6 L 600x600 COOL RUNNER (Daylight 800-870 mm.) | B7: =COUNTIF(DATABASE!$E$5:$E$72,A7) -> 7
A8: INJECT 2.5 L 700x700 COOL RUNNER VJ | B8: =COUNTIF(DATABASE!$E$5:$E$72,A8) -> 5
A9: INJ 350 T 700x700 COOL RUNNER | B9: =COUNTIF(DATABASE!$E$5:$E$72,A9) -> 3
A10: INJECT 0.8 L 450x510 | B10: =COUNTIF(DATABASE!$E$5:$E$72,A10) -> 9
A11: PRESS 510X510 | B11: =COUNTIF(DATABASE!$E$5:$E$72,A11) -> 4
A12: VACUUM 700x700 | B12: =COUNTIF(DATABASE!$E$5:$E$72,A12) -> 2
A13: VACUUM 510x510 | B13: =COUNTIF(DATABASE!$E$5:$E$72,A13) -> 2
... A15: INJECT 400T | B15: =COUNTIF(DATABASE!$E$5:$E$72,A15) -> 1
B16: =SUM(B2:B15) -> 67
